Workbook

Sheet Standalone Balance Sheet
A1: STEEL AUTHORITY OF INDIA LIMITED – STANDALONE BALANCE SHEET
A2: As at 31st March, 2025 | (₹ in Crore)
A3: Particulars | B3: FY 2024-25 (₹ Cr) | C3: FY 2023-24 (₹ Cr) | D3: YoY Change (₹ Cr)
A4: I. ASSETS
A5: Non-Current Assets
A6: Property, Plant & Equipment | B6: 65022.9 | C6: 65396.59 | D6: =B6-C6 -> -373.69
A7: Capital Work-in-Progress | B7: 7206.21 | C7: 6140.57 | D7: =B7-C7 -> 1065.64
A8: Right of Use Assets | B8: 6838.6 | C8: 5521.17 | D8: =B8-C8 -> 1317.43
A9: Investment Property | B9: 0.96 | C9: 0.99 | D9: =B9-C9 -> -0.03
A10: Other Intangible Assets | B10: 1425.69 | C10: 1488.84 | D10: =B10-C10 -> -63.15
A11: Non-Current Inventories (Mining Stripping) | B11: 4591.88 | C11: 4625.29 | D11: =B11-C11 -> -33.41
A12: Investments (Non-Current) | B12: 1758.93 | C12: 1694.07 | D12: =B12-C12 -> 64.86
A13: Trade Receivables (Non-Current) | B13: 0 | C13: 0 | D13: =B13-C13 -> 0
A14: Loans (Non-Current) | B14: 950.86 | C14: 877.3 | D14: =B14-C14 -> 73.56
A15: Other Financial Assets (Non-Current) | B15: 622.47 | C15: 444.24 | D15: =B15-C15 -> 178.23
A16: Non-Current Tax Assets (Net) | B16: 451.35 | C16: 374.7 | D16: =B16-C16 -> 76.65
A17: Other Non-Current Assets | B17: 2354.92 | C17: 3086.55 | D17: =B17-C17 -> -731.63
A18: Total Non-Current Assets | B18: =SUM(B6:B17) -> 91224.77 | C18: =SUM(C6:C17) -> 89650.31 | D18: =B18-C18 -> 1574.46
A19: Current Assets
A20: Inventories | B20: 29072.36 | C20: 32645.58 | D20: =B20-C20 -> -3573.22
A21: Trade Receivables (Current) | B21: 7557.15 | C21: 8308.72 | D21: =B21-C21 -> -751.57
A22: Cash & Cash Equivalents | B22: 285.62 | C22: 13.73 | D22: =B22-C22 -> 271.89
A23: Bank Balances (Other than above) | B23: 619.4 | C23: 527.87 | D23: =B23-C23 -> 91.53
A24: Loans (Current) | B24: 22.6 | C24: 28.31 | D24: =B24-C24 -> -5.71
A25: Other Financial Assets (Current) | B25: 1221.31 | C25: 1368.66 | D25: =B25-C25 -> -147.35
A26: Current Tax Assets (Net) | B26: 0 | C26: 433.11 | D26: =B26-C26 -> -433.11
A27: Other Current Assets | B27: 2910.94 | C27: 4541.05 | D27: =B27-C27 -> -1630.11
A28: Total Current Assets | B28: =SUM(B20:B27) -> 41689.38 | C28: =SUM(C20:C27) -> 47867.03 | D28: =B28-C28 -> -6177.65
A29: Assets Classified as Held for Sale | B29: 3.9 | C29: 15.11 | D29: =B29-C29 -> -11.21
A30: TOTAL ASSETS | B30: =B18+B28+B29 -> 132918.05 | C30: =C18+C28+C29 -> 137532.45 | D30: =B30-C30 -> -4614.4
A32: II. EQUITY AND LIABILITIES
A33: Equity
A34: Equity Share Capital | B34: 4130.53 | C34: 4130.53 | D34: =B34-C34 -> 0
A35: Other Equity | B35: 51525.88 | C35: 50000.01 | D35: =B35-C35 -> 1525.87
A36: Total Equity | B36: =SUM(B34:B35) -> 55656.41 | C36: =SUM(C34:C35) -> 54130.54 | D36: =B36-C36 -> 1525.87
A37: Non-Current Liabilities
A38: Borrowings (Non-Current) | B38: 10100.95 | C38: 9568.21 | D38: =B38-C38 -> 532.74
A39: Lease Liabilities (Non-Current) | B39: 6553.42 | C39: 5235.24 | D39: =B39-C39 -> 1318.18
A40: Trade Payables – MSME (Non-Current) | B40: 0 | C40: 0 | D40: =B40-C40 -> 0
A41: Trade Payables – Others (Non-Current) | B41: 0 | C41: 0 | D41: =B41-C41 -> 0
...

Sheet Standalone Income Statement
A1: STEEL AUTHORITY OF INDIA LIMITED – STANDALONE STATEMENT OF PROFIT & LOSS
A2: For the Year Ended 31st March, 2025 | (₹ in Crore)
A3: Particulars | B3: FY 2024-25 (₹ Cr) | C3: FY 2023-24 (₹ Cr) | D3: YoY Change (₹ Cr)
A4: INCOME
A5: Revenue from Operations | B5: 102478.19 | C5: 105374.59 | D5: =B5-C5 -> -2896.4
A6: Other Income | B6: 1134.41 | C6: 1148.06 | D6: =B6-C6 -> -13.65
A7: Total Income | B7: =B5+B6 -> 103612.6 | C7: =C5+C6 -> 106522.65 | D7: =B7-C7 -> -2910.05
A9: EXPENSES
A10: Cost of Materials Consumed | B10: 48952.89 | C10: 57618.84 | D10: =B10-C10 -> -8665.95
A11: Purchase of Stock-in-Trade | B11: 1856.98 | C11: 0 | D11: =B11-C11 -> 1856.98
A12: Changes in Inventories of FG, WIP & By-Products | B12: 92.13 | C12: -3352.92 | D12: =B12-C12 -> 3445.05
A13: Employee Benefits Expense | B13: 11658.54 | C13: 11747.92 | D13: =B13-C13 -> -89.38
A14: Finance Costs | B14: 2792.77 | C14: 2473.81 | D14: =B14-C14 -> 318.96
A15: Depreciation & Amortisation Expense | B15: 5649.57 | C15: 5277.45 | D15: =B15-C15 -> 372.12
A16: Other Expenses | B16: 29288.26 | C16: 28229.04 | D16: =B16-C16 -> 1059.22
A17: Total Expenses | B17: =SUM(B10:B16) -> 100291.14 | C17: =SUM(C10:C16) -> 101994.14 | D17: =B17-C17 -> -1703
A19: Profit Before Exceptional Items & Tax | B19: =B7-B17 -> 3321.46 | C19: =C7-C17 -> 4528.51 | D19: =B19-C19 -> -1207.05
A20: Add/(Less): Exceptional Items | B20: -312.64 | C20: -840.84 | D20: =B20-C20 -> 528.2
A21: Profit Before Tax (PBT) | B21: =B19+B20 -> 3008.82 | C21: =C19+C20 -> 3687.67 | D21: =B21-C21 -> -678.85
A23: TAX EXPENSE
A24: Current Tax | B24: 815.15 | C24: 605.54 | D24: =B24-C24 -> 209.61
A25: Deferred Tax | B25: 45.71 | C25: 349.02 | D25: =B25-C25 -> -303.31
A26: Total Tax Expense | B26: =B24+B25 -> 860.86 | C26: =C24+C25 -> 954.56 | D26: =B26-C26 -> -93.7
A28: Profit for the Year (PAT) | B28: =B21-B26 -> 2147.96 | C28: =C21-C26 -> 2733.11 | D28: =B28-C28 -> -585.15
A30: OTHER COMPREHENSIVE INCOME (OCI)
A31: Remeasurement of Defined Benefit Plans | B31: -387.74 | C31: -196.62 | D31: =B31-C31 -> -191.12
A32: Gain/(Loss) on Equity Instruments at FVTOCI | B32: 61.87 | C32: 73.9 | D32: =B32-C32 -> -12.03
A33: Income Tax on OCI Items | B33: 84.57 | C33: 0.55 | D33: =B33-C33 -> 84.02
A34: Total Other Comprehensive Income/(Loss) | B34: =SUM(B31:B33) -> -241.3 | C34: =SUM(C31:C33) -> -122.17 | D34: =B34-C34 -> -119.13
A36: Total Comprehensive Income for the Year | B36: =B28+B34 -> 1906.66 | C36: =C28+C34 -> 2610.94 | D36: =B36-C36 -> -704.28
A38: EARNINGS PER SHARE
A39: Number of Equity Shares (Face Value ₹10 each) | B39: 4130525289 | C39: 4130525289 | D39: =B39-C39 -> 0
A40: Basic & Diluted EPS (₹) | B40: 5.2 | C40: 6.62 | D40: =B40-C40 -> -1.42
A42: Source: SAIL Integrated Annual Report FY 2024-25, Page 79 – Standalone Statement of Profit & Loss

Sheet Standalone Cash Flow
A1: STEEL AUTHORITY OF INDIA LIMITED
A2: STANDALONE CASH FLOW STATEMENT
A3: For the year ended 31st March, 2025 | (in Crore INR)
A4: Sr No | B4: Section | C4: Particulars | D4: FY 2024-25 (Cr) | E4: FY 2023-24 (Cr) | F4: YoY Change (Cr)
B5: A | C5: A. CASH FLOW FROM OPERATING ACTIVITIES
A6: 1 | B6: A | C6: Profit before tax | D6: 3008.82 | E6: 3687.67 | F6: -678.85
A7: 2 | B7: A | C7: Depreciation and amortisation expenses | D7: 5649.57 | E7: 5277.45 | F7: 372.12
A8: 3 | B8: A | C8: Gain/Loss on disposal of fixed assets (net) | D8: 43.93 | E8: -130 | F8: 173.93
A9: 4 | B9: A | C9: Interest income | D9: -305.15 | E9: -306.45 | F9: 1.3
A10: 5 | B10: A | C10: Dividend income | D10: -273.18 | E10: -168.81 | F10: -104.37
A11: 6 | B11: A | C11: Finance costs | D11: 2792.77 | E11: 2473.81 | F11: 318.96
A12: 7 | B12: A | C12: Gain on sale of non-current investments | D12: -0.06 | E12: -
A13: 8 | B13: A | C13: Allowance for doubtful debts, loans and advances | D13: 164.39 | E13: 62.9 | F13: 101.49
A14: 9 | B14: A | C14: Other allowances | D14: 131.1 | E14: 148.67 | F14: -17.57
A15: 10 | B15: A | C15: Unclaimed balances and excess allowances written back | D15: -244.61 | E15: -328.85 | F15: 84.24
A16: 11 | B16: A | C16: Operating Profit before working capital changes | D16: 10967.58 | E16: 10716.39 | F16: 251.19
A17: 12 | B17: A | C17: Trade receivables | D17: 601.33 | E17: -2979.91 | F17: 3581.24
A18: 13 | B18: A | C18: Loans, other financial assets and other assets | D18: 2929.49 | E18: -1501.21 | F18: 4430.7
A19: 14 | B19: A | C19: Trade payable | D19: -4833.84 | E19: 993.52 | F19: -5827.36
A20: 15 | B20: A | C20: Other financial liabilities and other liabilities | D20: -2710.34 | E20: 974.11 | F20: -3684.45
A21: 16 | B21: A | C21: Provisions | D21: 79.98 | E21: -165.37 | F21: 245.35
A22: 17 | B22: A | C22: Inventories | D22: 3491.54 | E22: -5010.9 | F22: 8502.44
A23: 18 | B23: A | C23: Cash flow from operating activities post working capital changes | D23: 10525.74 | E23: 3026.63 | F23: 7499.11
A24: 19 | B24: A | C24: Income tax paid (net) | D24: -637.4 | E24: -93.44 | F24: -543.96
A25: 20 | B25: A | C25: Net cash generated/(used) in operating activities (A) | D25: 9888.34 | E25: 2933.19 | F25: 6955.15
B26: B | C26: B. CASH FLOWS FROM INVESTING ACTIVITIES
A27: 21 | B27: B | C27: Purchase of property, plant & equipment (incl. CWIP) and intangibles | D27: -6427.52 | E27: -4863.09 | F27: -1564.43
A28: 22 | B28: B | C28: Proceeds from sale/disposal of property, plant & equipment | D28: 843.72 | E28: 502.85 | F28: 340.87
A29: 23 | B29: B | C29: Purchase of current and non-current investments | D29: -2.92 | E29: -
A30: 24 | B30: B | C30: Movement in fixed deposits (net) | D30: -91.53 | E30: -280.94 | F30: 189.41
A31: 25 | B31: B | C31: Interest received | D31: 172.15 | E31: 192.11 | F31: -19.96
A32: 26 | B32: B | C32: Dividend received | D32: 273.18 | E32: 168.81 | F32: 104.37
A33: 27 | B33: B | C33: Net cash used in investing activities (B) | D33: -5232.92 | E33: -4280.26 | F33: -952.66
B34: C | C34: C. CASH FLOWS FROM FINANCING ACTIVITIES
A35: 28 | B35: C | C35: Proceeds from long-term borrowings | D35: 1250 | E35: 5000 | F35: -3750
A36: 29 | B36: C | C36: Repayment of long-term borrowings | D36: -1083.72 | E36: -2494.93 | F36: 1411.21
A37: 30 | B37: C | C37: Proceeds/(repayment) of short-term borrowings (net) | D37: -948.49 | E37: 2426.47 | F37: -3374.96
A38: 31 | B38: C | C38: Lease liabilities | D38: -822.31 | E38: -801.03 | F38: -21.28
A39: 32 | B39: C | C39: Finance cost paid | D39: -2365.96 | E39: -2156.57 | F39: -209.39
A40: 33 | B40: C | C40: Dividend paid | D40: -413.05 | E40: -619.58 | F40: 206.53
...

Sheet Standalone Notes (Account)
A1: STEEL AUTHORITY OF INDIA LIMITED
A2: NOTES TO STANDALONE FINANCIAL STATEMENTS – ACCOUNT FORMAT
A3: For the Year Ended 31st March, 2025 | All amounts in ₹ Crore | Prepared as per Ind AS
A5: NOTE 9: TRADE RECEIVABLES – NON CURRENT
A6: Sr No | B6: Particulars | C6: FY 2024-25 (₹ Cr) | D6: FY 2023-24 (₹ Cr)
A7: 1 | B7: Considered good - Secured | C7: - | D7: -
A8: 2 | B8: Considered good - Unsecured | C8: - | D8: -
A9: 3 | B9: Trade receivables which have significant increase in credit risk | C9: - | D9: -
A10: 4 | B10: Trade receivables - credit impaired | C10: 123.08 | D10: 132.59
A11: 5 | B11: Less: Allowance for credit losses | C11: (123.08) | D11: (132.59)
B12: TOTAL | C12: - | D12: -
A14: NOTE 10: LOANS – NON CURRENT
A15: Sr No | B15: Particulars | C15: FY 2024-25 (₹ Cr) | D15: FY 2023-24 (₹ Cr)
A16: 1 | B16: Loan to employees (Considered Good – Unsecured) | C16: 21.42 | D16: 25.09
A17: 2 | B17: Loan to others (incl. Indian Railways – Rowghat line) | C17: 931.64 | D17: 854.06
A18: 3 | B18: Sub-Total | C18: 953.06 | D18: 879.15
A19: 4 | B19: Less: Allowance for credit losses | C19: (2.20) | D19: (1.85)
B20: NET LOANS – NON CURRENT | C20: 950.86 | D20: 877.30
A22: NOTE 11: OTHER FINANCIAL ASSETS – NON CURRENT
A23: Sr No | B23: Particulars | C23: FY 2024-25 (₹ Cr) | D23: FY 2023-24 (₹ Cr)
A24: 1 | B24: Security deposits | C24: 316.83 | D24: 263.31
A25: 2 | B25: Bank deposits with more than 12 months maturity | C25: 31.67 | D25: 28.87
A26: 3 | B26: Advance for purchase of shares | C26: 0.06 | D26: 0.06
A27: 4 | B27: Claims recoverable | C27: 139.31 | D27: 122.23
A28: 5 | B28: Receivables other than trade | C28: 82.78 | D28: 62.57
A29: 6 | B29: Lease equalisation reserve | C29: 1.25 | D29: 1.25
A30: 7 | B30: Receivables from employees | C30: 0.99 | D30: 1.58
A31: 8 | B31: Other receivables (incl. township dues, BJCL) | C31: 98.00 | D31: 62.35
A32: 9 | B32: Gross Other Financial Assets – Non Current | C32: 670.89 | D32: 542.22
A33: 10 | B33: Less: Allowance for doubtful assets | C33: (48.42) | D33: (97.98)
B34: NET OTHER FINANCIAL ASSETS – NON CURRENT | C34: 622.47 | D34: 444.24
A36: NOTE 13: NON-CURRENT TAX ASSETS (NET)
A37: Sr No | B37: Particulars | C37: FY 2024-25 (₹ Cr) | D37: FY 2023-24 (₹ Cr)
A38: 1 | B38: Advance income tax (net of provision) | C38: 451.35 | D38: 374.70
B39: NON-CURRENT TAX ASSETS (NET) | C39: 451.35 | D39: 374.70
A41: NOTE 14: OTHER ASSETS – NON CURRENT
A42: Sr No | B42: Particulars | C42: FY 2024-25 (₹ Cr) | D42: FY 2023-24 (₹ Cr)
A43: 1 | B43: Capital advances | C43: 247.56 | D43: 238.38
A44: 2 | B44: Less: Allowance for doubtful capital advances | C44: (5.02) | D44: (5.02)
A45: 3 | B45: Net Capital advances | C45: 242.54 | D45: 233.36
...

Sheet Consolidated Balance Sheet
A1: STEEL AUTHORITY OF INDIA LIMITED – CONSOLIDATED BALANCE SHEET
A2: As at 31st March, 2025 | (₹ in Crore)
A3: Particulars | B3: FY 2024-25 (₹ Cr) | C3: FY 2023-24 (₹ Cr) | D3: YoY Change (₹ Cr)
A4: I. ASSETS
A5: Non-Current Assets
A6: Property, Plant & Equipment | B6: 65061.37 | C6: 65415.07 | D6: =B6-C6 -> -353.7
A7: Capital Work-in-Progress | B7: 7206.21 | C7: 6140.57 | D7: =B7-C7 -> 1065.64
A8: Right of Use Assets | B8: 6838.6 | C8: 5521.19 | D8: =B8-C8 -> 1317.41
A9: Investment Property | B9: 0.96 | C9: 0.99 | D9: =B9-C9 -> -0.03
A10: Other Intangible Assets | B10: 1425.71 | C10: 1488.86 | D10: =B10-C10 -> -63.15
A11: Investments – Equity Method (JVs/Associates) | B11: 4603.25 | C11: 4278.55 | D11: =B11-C11 -> 324.7
A12: Non-Current Inventories (Mining Stripping) | B12: 4591.88 | C12: 4625.29 | D12: =B12-C12 -> -33.41
A13: Investments (Non-Current) | B13: 372.33 | C13: 310.47 | D13: =B13-C13 -> 61.86
A14: Trade Receivables (Non-Current) | B14: 0 | C14: 0 | D14: =B14-C14 -> 0
A15: Loans (Non-Current) | B15: 950.93 | C15: 877.37 | D15: =B15-C15 -> 73.56
A16: Other Financial Assets (Non-Current) | B16: 623.13 | C16: 444.96 | D16: =B16-C16 -> 178.17
A17: Non-Current Tax Assets (Net) | B17: 452.14 | C17: 374.78 | D17: =B17-C17 -> 77.36
A18: Other Non-Current Assets | B18: 2355.95 | C18: 3092.79 | D18: =B18-C18 -> -736.84
A19: Total Non-Current Assets | B19: =SUM(B6:B18) -> 94482.46 | C19: =SUM(C6:C18) -> 92570.89 | D19: =B19-C19 -> 1911.57
A20: Current Assets
A21: Inventories | B21: 29151.45 | C21: 32721.45 | D21: =B21-C21 -> -3570
A22: Trade Receivables (Current) | B22: 7609.94 | C22: 8355.37 | D22: =B22-C22 -> -745.43
A23: Cash & Cash Equivalents | B23: 291.58 | C23: 69.38 | D23: =B23-C23 -> 222.2
A24: Bank Balances (Other than above) | B24: 675.3 | C24: 603.57 | D24: =B24-C24 -> 71.73
A25: Loans (Current) | B25: 22.6 | C25: 28.31 | D25: =B25-C25 -> -5.71
A26: Other Financial Assets (Current) | B26: 1221.76 | C26: 1369.07 | D26: =B26-C26 -> -147.31
A27: Current Tax Assets | B27: 0 | C27: 433.11 | D27: =B27-C27 -> -433.11
A28: Other Current Assets | B28: 2911.95 | C28: 4542.32 | D28: =B28-C28 -> -1630.37
A29: Total Current Assets | B29: =SUM(B21:B28) -> 41884.58 | C29: =SUM(C21:C28) -> 48122.58 | D29: =B29-C29 -> -6238
A30: Assets Classified as Held for Sale | B30: 3.9 | C30: 15.11 | D30: =B30-C30 -> -11.21
A31: TOTAL ASSETS | B31: =B19+B29+B30 -> 136370.94 | C31: =C19+C29+C30 -> 140708.58 | D31: =B31-C31 -> -4337.64
A33: II. EQUITY AND LIABILITIES
A34: Equity
A35: Equity Share Capital | B35: 4130.53 | C35: 4130.53 | D35: =B35-C35 -> 0
A36: Other Equity | B36: 54775.08 | C36: 52970.69 | D36: =B36-C36 -> 1804.39
A37: Non-Controlling Interest | B37: -0.01 | C37: 0.01 | D37: =B37-C37 -> -0.02
A38: Total Equity | B38: =SUM(B35:B37) -> 58905.6 | C38: =SUM(C35:C37) -> 57101.23 | D38: =B38-C38 -> 1804.37
A39: Non-Current Liabilities
A40: Borrowings (Non-Current) | B40: 10100.95 | C40: 9568.21 | D40: =B40-C40 -> 532.74
A41: Lease Liabilities (Non-Current) | B41: 6553.42 | C41: 5235.25 | D41: =B41-C41 -> 1318.17
...

Sheet Consolidated Income Statement
A1: STEEL AUTHORITY OF INDIA LIMITED – CONSOLIDATED STATEMENT OF PROFIT & LOSS
A2: For the Year Ended 31st March, 2025 | (₹ in Crore)
A3: Particulars | B3: FY 2024-25 (₹ Cr) | C3: FY 2023-24 (₹ Cr) | D3: YoY Change (₹ Cr)
A4: INCOME
A5: Revenue from Operations | B5: 102479.06 | C5: 105378.33 | D5: =B5-C5 -> -2899.27
A6: Other Income | B6: 875.03 | C6: 1066.96 | D6: =B6-C6 -> -191.93
A7: Total Income | B7: =B5+B6 -> 103354.09 | C7: =C5+C6 -> 106445.29 | D7: =B7-C7 -> -3091.2
A9: EXPENSES
A10: Cost of Materials Consumed | B10: 49051.46 | C10: 57709.26 | D10: =B10-C10 -> -8657.8
A11: Purchase of Stock-in-Trade | B11: 1856.98 | C11: 0 | D11: =B11-C11 -> 1856.98
A12: Changes in Inventories of FG, WIP & By-Products | B12: 88.75 | C12: -3354.77 | D12: =B12-C12 -> 3443.52
A13: Employee Benefits Expense | B13: 11674.95 | C13: 11765.72 | D13: =B13-C13 -> -90.77
A14: Finance Costs | B14: 2793.17 | C14: 2473.86 | D14: =B14-C14 -> 319.31
A15: Depreciation & Amortisation Expense | B15: 5650.68 | C15: 5278.37 | D15: =B15-C15 -> 372.31
A16: Other Expenses | B16: 29160.71 | C16: 28108.81 | D16: =B16-C16 -> 1051.9
A17: Total Expenses | B17: =SUM(B10:B16) -> 100276.7 | C17: =SUM(C10:C16) -> 101981.25 | D17: =B17-C17 -> -1704.55
A19: Profit Before Share of JV/Associates, Exceptional Items & Tax | B19: =B7-B17 -> 3077.39 | C19: =C7-C17 -> 4464.04 | D19: =B19-C19 -> -1386.65
A20: Share of Profit from JVs/Associates (Equity Method) | B20: 486.78 | C20: 438.61 | D20: =B20-C20 -> 48.17
A21: Profit Before Exceptional Items & Tax | B21: =B19+B20 -> 3564.17 | C21: =C19+C20 -> 4902.65 | D21: =B21-C21 -> -1338.48
A22: Add/(Less): Exceptional Items | B22: -312.64 | C22: -840.84 | D22: =B22-C22 -> 528.2
A23: Profit Before Tax (PBT) | B23: =B21+B22 -> 3251.53 | C23: =C21+C22 -> 4061.81 | D23: =B23-C23 -> -810.28
A25: TAX EXPENSE
A26: Current Tax | B26: 821.32 | C26: 612.79 | D26: =B26-C26 -> 208.53
A27: Deferred Tax | B27: 58.41 | C27: 382.35 | D27: =B27-C27 -> -323.94
A28: Total Tax Expense | B28: =B26+B27 -> 879.73 | C28: =C26+C27 -> 995.14 | D28: =B28-C28 -> -115.41
A30: Profit for the Year (PAT) | B30: =B23-B28 -> 2371.8 | C30: =C23-C28 -> 3066.67 | D30: =B30-C30 -> -694.87
A32: PROFIT ATTRIBUTION
A33: Attributable to Owners of the Parent | B33: 2371.82 | C33: 3066.67 | D33: =B33-C33 -> -694.85
A34: Attributable to Non-Controlling Interest | B34: -0.02 | C34: 0 | D34: =B34-C34 -> -0.02
A36: OTHER COMPREHENSIVE INCOME (OCI)
A37: Remeasurement of Defined Benefit Plans | B37: -387.98 | C37: -196.64 | D37: =B37-C37 -> -191.34
A38: Gain/(Loss) on Equity Instruments at FVTOCI | B38: 61.87 | C38: 73.9 | D38: =B38-C38 -> -12.03
A39: Income Tax on OCI (Items not reclassified) | B39: 84.63 | C39: 0.55 | D39: =B39-C39 -> 84.08
A40: Share of OCI of Associates & JVs (Equity Method) | B40: 54.84 | C40: 29.65 | D40: =B40-C40 -> 25.19
A41: Total Other Comprehensive Income/(Loss) | B41: =SUM(B37:B40) -> -186.64 | C41: =SUM(C37:C40) -> -92.54 | D41: =B41-C41 -> -94.1
A43: Total Comprehensive Income for the Year | B43: =B30+B41 -> 2185.16 | C43: =C30+C41 -> 2974.13 | D43: =B43-C43 -> -788.97
A45: EARNINGS PER SHARE
A46: Number of Equity Shares (Face Value ₹10 each) | B46: 4130525289 | C46: 4130525289 | D46: =B46-C46 -> 0
A47: Basic & Diluted EPS (₹) | B47: 5.74 | C47: 7.42 | D47: =B47-C47 -> -1.68
A49: Source: SAIL Integrated Annual Report FY 2024-25, Page 265 – Consolidated Statement of Profit & Loss

Sheet Consolidated Cash Flow
A1: STEEL AUTHORITY OF INDIA LIMITED
A2: CONSOLIDATED CASH FLOW STATEMENT
A3: For the year ended 31st March, 2025 | (in Crore INR)
A4: Sr No | B4: Section | C4: Particulars | D4: FY 2024-25 (Cr) | E4: FY 2023-24 (Cr) | F4: YoY Change (Cr)
B5: A | C5: A. CASH FLOW FROM OPERATING ACTIVITIES
A6: 1 | B6: A | C6: Profit before tax | D6: 3251.53 | E6: 4061.81 | F6: -810.28
A7: 2 | B7: A | C7: Depreciation and amortisation expenses | D7: 5650.68 | E7: 5278.37 | F7: 372.31
A8: 3 | B8: A | C8: Gain/Loss on disposal of fixed assets (net) | D8: 43.93 | E8: -130 | F8: 173.93
A9: 4 | B9: A | C9: Interest income | D9: -311.11 | E9: -316.52 | F9: 5.41
A10: 5 | B10: A | C10: Dividend income | D10: -7.02 | E10: -5.52 | F10: -1.5
A11: 6 | B11: A | C11: Finance costs | D11: 2793.17 | E11: 2473.86 | F11: 319.31
A12: 7 | B12: A | C12: Gain on sale of non-current investments | D12: -0.06 | E12: -
A13: 8 | B13: A | C13: Allowance for doubtful debts, loans and advances | D13: 164.84 | E13: 63.07 | F13: 101.77
A14: 9 | B14: A | C14: Other allowances | D14: 131.78 | E14: 149.27 | F14: -17.49
A15: 10 | B15: A | C15: Share of profit from joint ventures | D15: -486.78 | E15: -438.61 | F15: -48.17
A16: 11 | B16: A | C16: Unclaimed balances and excess allowances written back | D16: -244.63 | E16: -471.71 | F16: 227.08
A17: 12 | B17: A | C17: Operating Profit before working capital changes | D17: 10986.33 | E17: 10664.02 | F17: 322.31
A18: 13 | B18: A | C18: Trade receivables | D18: 594.74 | E18: -2999.24 | F18: 3593.98
A19: 14 | B19: A | C19: Loans, other financial assets and other assets | D19: 2932.18 | E19: -1422.58 | F19: 4354.76
A20: 15 | B20: A | C20: Trade payable | D20: -4828.54 | E20: 993.45 | F20: -5821.99
A21: 16 | B21: A | C21: Other financial liabilities and other liabilities | D21: -2691.93 | E21: 980.98 | F21: -3672.91
A22: 17 | B22: A | C22: Provisions | D22: 77.97 | E22: -163.42 | F22: 241.39
A23: 18 | B23: A | C23: Inventories | D23: 3487.64 | E23: -5038.74 | F23: 8526.38
A24: 19 | B24: A | C24: Cash flow from operating activities post working capital changes | D24: 10558.39 | E24: 3014.47 | F24: 7543.92
... A26: 21 | B26: A | C26: Net cash generated/(used) in operating activities (A) | D26: 9914.3 | E26: 2910.88 | F26: 7003.42
B27: B | C27: B. CASH FLOWS FROM INVESTING ACTIVITIES
A28: 22 | B28: B | C28: Purchase of property, plant & equipment (incl. CWIP) and intangibles | D28: -6221.15 | E28: -4710.69 | F28: -1510.46
A29: 23 | B29: B | C29: Proceeds from sale/disposal of property, plant & equipment | D29: 843.72 | E29: 503.16 | F29: 340.56
A30: 24 | B30: B | C30: Purchase of current and non-current investments | D30: -2.99 | E30: -
A31: 25 | B31: B | C31: Movement in fixed deposits (net) | D31: -71.73 | E31: -254.6 | F31: 182.87
A32: 26 | B32: B | C32: Interest received | D32: 176.63 | E32: 196.07 | F32: -19.44
A33: 27 | B33: B | C33: Dividend received | D33: 7.02 | E33: 5.52 | F33: 1.5
A34: 28 | B34: B | C34: Net cash used in investing activities (B) | D34: -5268.5 | E34: -4260.54 | F34: -1007.96
B35: C | C35: C. CASH FLOWS FROM FINANCING ACTIVITIES
A36: 29 | B36: C | C36: Proceeds from long-term borrowings | D36: 1250 | E36: 5000 | F36: -3750
A37: 30 | B37: C | C37: Repayment of long-term borrowings | D37: -1083.72 | E37: -2494.93 | F37: 1411.21
A38: 31 | B38: C | C38: Proceeds/(repayment) of short-term borrowings (net) | D38: -956.13 | E38: 2434.12 | F38: -3390.25
A39: 32 | B39: C | C39: Lease liabilities | D39: -822.34 | E39: -801.03 | F39: -21.31
A40: 33 | B40: C | C40: Finance cost paid | D40: -2398.36 | E40: -2156.63 | F40: -241.73
A41: 34 | B41: C | C41: Dividend paid | D41: -413.05 | E41: -619.58 | F41: 206.53
...

Sheet Consolidated Notes (Account)
A1: STEEL AUTHORITY OF INDIA LIMITED
A2: NOTES TO CONSOLIDATED FINANCIAL STATEMENTS – ACCOUNT FORMAT
A3: For the Year Ended 31st March, 2025 | All amounts in ₹ Crore | Prepared as per Ind AS
A5: NOTE 9: TRADE RECEIVABLES – NON CURRENT
A6: Sr No | B6: Particulars | C6: FY 2024-25 (₹ Cr) | D6: FY 2023-24 (₹ Cr)
A7: 1 | B7: Considered good - Secured | C7: - | D7: -
A8: 2 | B8: Considered good - Unsecured | C8: - | D8: -
A9: 3 | B9: Trade receivables which have significant increase in credit risk | C9: - | D9: -
A10: 4 | B10: Trade receivables - credit impaired | C10: 129.25 | D10: 138.44
A11: 5 | B11: Less: Allowance for credit losses | C11: (129.25) | D11: (138.44)
B12: TOTAL | C12: - | D12: -
A14: NOTE 10: LOANS – NON CURRENT
A15: Sr No | B15: Particulars | C15: FY 2024-25 (₹ Cr) | D15: FY 2023-24 (₹ Cr)
A16: 1 | B16: Loan to employees (Considered Good – Unsecured) | C16: 21.42 | D16: 25.09
A17: 2 | B17: Loan to others (incl. Indian Railways – Rowghat line) | C17: 931.71 | D17: 854.13
A18: 3 | B18: Sub-Total | C18: 953.13 | D18: 879.22
A19: 4 | B19: Less: Allowance for credit losses | C19: (2.20) | D19: (1.85)
B20: NET LOANS – NON CURRENT | C20: 950.93 | D20: 877.37
A22: NOTE 11: OTHER FINANCIAL ASSETS – NON CURRENT
A23: Sr No | B23: Particulars | C23: FY 2024-25 (₹ Cr) | D23: FY 2023-24 (₹ Cr)
A24: 1 | B24: Security deposits | C24: 317.54 | D24: 264.25
A25: 2 | B25: Bank deposits with more than 12 months maturity | C25: 31.67 | D25: 28.87
A26: 3 | B26: Claims recoverable | C26: 139.56 | D26: 122.48
A27: 4 | B27: Receivables other than trade | C27: 82.78 | D27: 62.57
A28: 5 | B28: Lease equalisation reserve | C28: 1.25 | D28: 1.25
A29: 6 | B29: Receivables from employees | C29: 0.99 | D29: 1.58
A30: 7 | B30: Other receivables (incl. township dues, BJCL) | C30: 98.00 | D30: 62.35
A31: 8 | B31: Gross Other Financial Assets – Non Current | C31: 671.79 | D31: 543.35
A32: 9 | B32: Less: Allowance for doubtful assets | C32: (48.66) | D32: (98.39)
B33: NET OTHER FINANCIAL ASSETS – NON CURRENT | C33: 623.13 | D33: 444.96
A35: NOTE 13: NON-CURRENT TAX ASSETS (NET)
A36: Sr No | B36: Particulars | C36: FY 2024-25 (₹ Cr) | D36: FY 2023-24 (₹ Cr)
A37: 1 | B37: Advance income tax (net of provision) | C37: 452.14 | D37: 374.78
B38: NON-CURRENT TAX ASSETS (NET) | C38: 452.14 | D38: 374.78
A40: NOTE 14: OTHER ASSETS – NON CURRENT
A41: Sr No | B41: Particulars | C41: FY 2024-25 (₹ Cr) | D41: FY 2023-24 (₹ Cr)
A42: 1 | B42: Capital advances | C42: 247.56 | D42: 242.75
A43: 2 | B43: Less: Allowance for doubtful capital advances | C43: (5.02) | D43: (5.02)
A44: 3 | B44: Net Capital advances | C44: 242.54 | D44: 237.73
A45: 4 | B45: Deposit with Government authorities – Excise | C45: 102.52 | D45: 89.73
...

Sheet WACC
B1: STEEL AUTHORITY OF INDIA LIMITED
B3: Wegithr Average Cost Of Capital
B5: All Figure are in INR unless Stated Otherwise
K7: Weighted Average Cost of Capital
G8: Equity / | H8: Debt/ | I8: Cost of | J8: Cost of
B9: Name oF Company | C9: Country | D9: Total Equity | E9: Total Debt | F9: Tax Rate 1 | G9: Weights | H9: Weights | I9: Equity | J9: Debt | K9: Cost of Equity | N9: =I10 -> 0.14245113
B10: STEEL AUTHORITY OF INDIA LIMITED | C10: Iindia | D10: =IFERROR(SUM('Consolidated Balance Sheet'!B35:B36),0) -> 58905.61 | E10: =IFERROR(SUM('Consolidated Balance Sheet'!B40,'Consolidated Balance Sheet'!B41,'Consolidated Balance Sheet'!B50,'Consolidated Balance Sheet'!B51),0) -> 36933.94 | F10: 0.3 | G10: =IFERROR(D10/SUM(D10:E10),0) -> 0.61462736 | H10: =IFERROR(E10/(SUM(D10:E10)),0) -> 0.38537264 | I10: 0.14245113 | J10: =L25 -> 0.052938273 | K10: Equity Weight | N10: =G10 -> 0.61462736
K11: Cost of Debt | N11: =J10 -> 0.052938273
B12: Total Capital | D12: =SUM(D10:E10) -> 95839.55 | G12: =G10+H10 -> 1 | K12: Debt Weight | N12: =H10 -> 0.38537264
K13: WACC | N13: =(N9*N10)+(N11*N12) -> 0.10795532
B15: 1. Tax Rate considered as Marginal Tax Rate for the country
B18: Working Notes -No.1
B19: STEEL AUTHORITY OF INDIA LIMITED Dividends | H19: Working Note No .2 Kd
B21: Announcement Date | C21: Final Dividend (Rs) | D21: Interim Dividend (Rs | E21: Total Dividend (Rs) | F21: Yearly Growth rate | I21: Cost of Debt | M21: Calculation oF Interest
B22: 2011 | C22: 1.2 | D22: 0 | E22: 1.2
B23: 2012 | C23: 0.8 | D23: 1.2 | E23: 2 | F23: =E23/E22-1 -> 0.66666667 | I23: Pre-Tax Cost of Debt | L23: =O23 -> 0.075626104 | N23: Interest | O23: =IFERROR('Consolidated Income Statement'!B14/WACC!E10,0) -> 0.075626104
B24: 2013 | C24: 0.4 | D24: 1.6 | E24: 2 | F24: =E24/E23-1 -> 0 | I24: Tax | L24: =F10 -> 0.3
B25: 2014 | C25: 0 | D25: 2.02 | E25: 2.02 | F25: =E25/E24-1 -> 0.01 | I25: After Tax Cost Debt | L25: =L23*(1-L24) -> 0.052938273
B26: 2015 | C26: 0.25 | D26: 1.75 | E26: 2 | F26: =E26/E25-1 -> -0.0099009901
B27: 2019 | C27: 0.5 | D27: 0 | E27: 0.5 | F27: =E27/E26-1 -> -0.75
B28: 2021 | C28: 1.8 | D28: 5 | E28: 6.8 | F28: =E28/E27-1 -> 12.6
B29: 2022 | C29: 2.25 | D29: 2.5 | E29: 4.75 | F29: =E29/E28-1 -> -0.30147059
B30: 2023 | C30: 0.5 | D30: 1 | E30: 1.5 | F30: =E30/E29-1 -> -0.68421053
B31: 2024 | C31: 1 | D31: 1 | E31: 2 | F31: =E31/E30-1 -> 0.33333333
B32: 2025 | C32: 1.6 | D32: 0 | E32: 1.6 | F32: =E32/E31-1 -> -0.2
E34: Avearge Growth | F34: =AVERAGE(F23:F32) -> 1.1664418
E35: CAGR | F35: =_xlfn.RRI(10,E22,E32) -> 0.029186009 | G35: =F35 -> 0.029186009
E36: Median | F36: =MEDIAN(F23:F32) -> -0.004950495
B37: Working Note.1(a) | E37: Market Price | F37: 154.94 | G37: Taken From Nse
B38: D1 | C38: =IFERROR(E32*(1+G35),0) -> 1.6466976
B39: Ke | C39: =IFERROR((C38/F37)+G35,0) -> 0.039813979
B42: Capital Assets Pricing Model
C44: Nifty 50
B46: Date | C46: Close Price | D46: Yearly Return | J46: Date | K46: Close Price | L46: Yearly Return
B47: 42508 | C47: 7870.15 | E47: Average Return | G47: =AVERAGE(D48:D56) -> 0.15973165 | H47: =MEDIAN(D48:D56) -> 0.11637623 | J47: 42508 | K47: 42.25 | N47: Average Return | P47: =AVERAGE(L48:L56) -> 0.45777935 | Q47: =MEDIAN(L48:L56) -> -0.024822695
B48: 42873 | C48: 9429.45 | D48: =C48/C47-1 -> 0.19812837 | E48: CAGR | G48: =_xlfn.RRI(10,C47,C56) -> 0.12227899 | J48: 42873 | K48: 60.4 | L48: =IFERROR(K48/K47-1,0) -> 0.4295858 | N48: CAGR | P48: =_xlfn.RRI(10,K47,K56) -> 0.11234121
B49: 43238 | C49: 10596.4 | D49: =C49/C48-1 -> 0.12375589 | E49: Total Market Return | G49: =G47 -> 0.15973165 | J49: 43238 | K49: 73.6 | L49: =IFERROR(K49/K48-1,0) -> 0.21854305 | N49: Stock Return | P49: =P47 -> 0.45777935
B50: 43605 | C50: 11828.25 | D50: =C50/C49-1 -> 0.11625175 | J50: 43605 | K50: 51.45 | L50: =IFERROR(K50/K49-1,0) -> -0.30095109
B51: 43969 | C51: 8823.25 | D51: =C51/C50-1 -> -0.2540528 | J51: 43969 | K51: 27.45 | L51: =IFERROR(K51/K50-1,0) -> -0.4664723 | N51: 0.0638 | O51: RF | P51: https://www.bloomberg.com/markets/rates-bonds
B52: 44334 | C52: 15108.1 | D52: =C52/C51-1 -> 0.71230556 | J52: 44334 | K52: 131.95 | L52: =IFERROR(K52/K51-1,0) -> 3.8069217 | N52: =Beta!N7 -> 1.620296 | O52: Beta1
...

Sheet Beta
B2: STEEL AUTHORITY OF INDIA LIMITED | H2: Nifty 50 | P2: JINDALSTEL | T2: NSLNISP | X2: JSWSTEEL | AB2: TATASTEEL
B3: Symbol | C3: Series | D3: Date | E3: Close Price | F3: Daiy Return | H3: Date | I3: Close | J3: Daily return | P3: Date | Q3: Close | R3: Daily return | T3: Date | U3: Close | V3: Daily return | X3: Date | Y3: Close Price | Z3: Daily return | AB3: Date | AC3: Close Price | AD3: Daily return
B4: SAIL | C4: EQ | D4: 45658 | E4: 112.93 | H4: 45658 | I4: 23742.9 | P4: 45658 | Q4: 938.1 | T4: 45658 | U4: 43.59 | X4: 45658 | Y4: 905.45 | AB4: 45658 | AC4: 136.74
B5: SAIL | C5: EQ | D5: 45659 | E5: 114.07 | F5: =E5/E4-1 -> 0.010094749 | H5: 45659 | I5: 24188.65 | J5: =I5/I4-1 -> 0.018774034 | P5: 45659 | Q5: 941.7 | R5: =Q5/Q4-1 -> 0.003837544 | T5: 45659 | U5: 43.63 | V5: =U5/U4-1 -> 0.00091764166 | X5: 45659 | Y5: 912.5 | Z5: =Y5/Y4-1 -> 0.0077861837 | AB5: 45659 | AC5: 138.18 | AD5: =AC5/AC4-1 -> 0.010530935
B6: SAIL | C6: EQ | D6: 45660 | E6: 114.17 | F6: =E6/E5-1 -> 0.00087665469 | H6: 45660 | I6: 24004.75 | J6: =I6/I5-1 -> -0.0076027393 | L6: STEEL AUTHORITY OF INDIA LIMITED | N6: =SLOPE(F5:F252,J$5:J$252) -> 1.620296 | O6: BETA | P6: 45660 | Q6: 957.85 | R6: =Q6/Q5-1 -> 0.017149835 | T6: 45660 | U6: 43.44 | V6: =U6/U5-1 -> -0.0043548017 | X6: 45660 | Y6: 915.05 | Z6: =Y6/Y5-1 -> 0.0027945205 | AB6: 45660 | AC6: 138.36 | AD6: =AC6/AC5-1 -> 0.0013026487
B7: SAIL | C7: EQ | D7: 45663 | E7: 110.42 | F7: =E7/E6-1 -> -0.032845756 | H7: 45663 | I7: 23616.05 | J7: =I7/I6-1 -> -0.016192629 | N7: =_xlfn.COVARIANCE.S(F5:F252,J$5:J$252)/_xlfn.VAR.S(J$5:J$252) -> 1.620296 | P7: 45663 | Q7: 939.35 | R7: =Q7/Q6-1 -> -0.019314089 | T7: 45663 | U7: 42.13 | V7: =U7/U6-1 -> -0.030156538 | X7: 45663 | Y7: 900.9 | Z7: =Y7/Y6-1 -> -0.015463636 | AB7: 45663 | AC7: 132.18 | AD7: =AC7/AC6-1 -> -0.044666088
B8: SAIL | C8: EQ | D8: 45664 | E8: 111.47 | F8: =E8/E7-1 -> 0.0095091469 | H8: 45664 | I8: 23707.9 | J8: =I8/I7-1 -> 0.0038893041 | P8: 45664 | Q8: 941.45 | R8: =Q8/Q7-1 -> 0.0022355884 | T8: 45664 | U8: 42.81 | V8: =U8/U7-1 -> 0.016140517 | X8: 45664 | Y8: 911.8 | Z8: =Y8/Y7-1 -> 0.012099012 | AB8: 45664 | AC8: 133.38 | AD8: =AC8/AC7-1 -> 0.0090785293
B9: SAIL | C9: EQ | D9: 45665 | E9: 109.76 | F9: =E9/E8-1 -> -0.01534045 | H9: 45665 | I9: 23688.95 | J9: =I9/I8-1 -> -0.00079931162 | P9: 45665 | Q9: 942.55 | R9: =Q9/Q8-1 -> 0.0011684104 | T9: 45665 | U9: 42.15 | V9: =U9/U8-1 -> -0.015416959 | X9: 45665 | Y9: 902.3 | Z9: =Y9/Y8-1 -> -0.010418952 | AB9: 45665 | AC9: 132.64 | AD9: =AC9/AC8-1 -> -0.0055480582
B10: SAIL | C10: EQ | D10: 45666 | E10: 108.26 | F10: =E10/E9-1 -> -0.013666181 | H10: 45666 | I10: 23526.5 | J10: =I10/I9-1 -> -0.0068576277 | P10: 45666 | Q10: 931.55 | R10: =Q10/Q9-1 -> -0.011670468 | T10: 45666 | U10: 41.71 | V10: =U10/U9-1 -> -0.010438909 | X10: 45666 | Y10: 890.95 | Z10: =Y10/Y9-1 -> -0.012578965 | AB10: 45666 | AC10: 129.93 | AD10: =AC10/AC9-1 -> -0.020431242
B11: SAIL | C11: EQ | D11: 45667 | E11: 106.03 | F11: =E11/E10-1 -> -0.020598559 | H11: 45667 | I11: 23431.5 | J11: =I11/I10-1 -> -0.0040379997 | L11: JINDALSTEL | N11: =SLOPE(R5:R252,J5:J252) -> 1.3021319 | O11: BETA | P11: 45667 | Q11: 917.7 | R11: =Q11/Q10-1 -> -0.014867694 | T11: 45667 | U11: 40.71 | V11: =U11/U10-1 -> -0.023975066 | X11: 45667 | Y11: 900.1 | Z11: =Y11/Y10-1 -> 0.010269937 | AB11: 45667 | AC11: 127.43 | AD11: =AC11/AC10-1 -> -0.01924113
B12: SAIL | C12: EQ | D12: 45670 | E12: 100.09 | F12: =E12/E11-1 -> -0.056021881 | H12: 45670 | I12: 23085.95 | J12: =I12/I11-1 -> -0.014747242 | N12: =_xlfn.COVARIANCE.S(R5:R252,J$5:J$252)/_xlfn.VAR.S($J5:J$252) -> 1.3021319 | P12: 45670 | Q12: 876.7 | R12: =Q12/Q11-1 -> -0.04467691 | T12: 45670 | U12: 38.47 | V12: =U12/U11-1 -> -0.055023336 | X12: 45670 | Y12: 883.75 | Z12: =Y12/Y11-1 -> -0.018164648 | AB12: 45670 | AC12: 122.93 | AD12: =AC12/AC11-1 -> -0.035313505
B13: SAIL | C13: EQ | D13: 45671 | E13: 105.88 | F13: =E13/E12-1 -> 0.057847937 | H13: 45671 | I13: 23176.05 | J13: =I13/I12-1 -> 0.0039028067 | P13: 45671 | Q13: 909.9 | R13: =Q13/Q12-1 -> 0.037869283 | T13: 45671 | U13: 40.84 | V13: =U13/U12-1 -> 0.061606447 | X13: 45671 | Y13: 906.05 | Z13: =Y13/Y12-1 -> 0.02523338 | AB13: 45671 | AC13: 126.93 | AD13: =AC13/AC12-1 -> 0.032538843
B14: SAIL | C14: EQ | D14: 45672 | E14: 105.21 | F14: =E14/E13-1 -> -0.0063279184 | H14: 45672 | I14: 23213.2 | J14: =I14/I13-1 -> 0.0016029479 | P14: 45672 | Q14: 910.25 | R14: =Q14/Q13-1 -> 0.00038465765 | T14: 45672 | U14: 41 | V14: =U14/U13-1 -> 0.0039177277 | X14: 45672 | Y14: 904.05 | Z14: =Y14/Y13-1 -> -0.0022073837 | AB14: 45672 | AC14: 126.53 | AD14: =AC14/AC13-1 -> -0.0031513433
B15: SAIL | C15: EQ | D15: 45673 | E15: 107.52 | F15: =E15/E14-1 -> 0.021956088 | H15: 45673 | I15: 23311.8 | J15: =I15/I14-1 -> 0.0042475833 | L15: NSLNISP | N15: =SLOPE(V5:V252,J$5:J$252) -> 1.5007839 | O15: BETA | P15: 45673 | Q15: 917.85 | R15: =Q15/Q14-1 -> 0.0083493546 | T15: 45673 | U15: 41.59 | V15: =U15/U14-1 -> 0.014390244 | X15: 45673 | Y15: 906.8 | Z15: =Y15/Y14-1 -> 0.0030418672 | AB15: 45673 | AC15: 127.81 | AD15: =AC15/AC14-1 -> 0.010116178
B16: SAIL | C16: EQ | D16: 45674 | E16: 108.82 | F16: =E16/E15-1 -> 0.012090774 | H16: 45674 | I16: 23203.2 | J16: =I16/I15-1 -> -0.0046585849 | N16: =_xlfn.COVARIANCE.S(V5:V252,J$5:J$252)/_xlfn.VAR.S(J$5:J$252) -> 1.5007839 | P16: 45674 | Q16: 924.65 | R16: =Q16/Q15-1 -> 0.007408618 | T16: 45674 | U16: 41.61 | V16: =U16/U15-1 -> 0.00048088483 | X16: 45674 | Y16: 908.6 | Z16: =Y16/Y15-1 -> 0.0019850022 | AB16: 45674 | AC16: 130.28 | AD16: =AC16/AC15-1 -> 0.019325561
B17: SAIL | C17: EQ | D17: 45677 | E17: 109.87 | F17: =E17/E16-1 -> 0.0096489616 | H17: 45677 | I17: 23344.75 | J17: =I17/I16-1 -> 0.0061004517 | P17: 45677 | Q17: 933.8 | R17: =Q17/Q16-1 -> 0.0098956362 | T17: 45677 | U17: 42.15 | V17: =U17/U16-1 -> 0.01297765 | X17: 45677 | Y17: 919.2 | Z17: =Y17/Y16-1 -> 0.0116663 | AB17: 45677 | AC17: 131.66 | AD17: =AC17/AC16-1 -> 0.01059257
B18: SAIL | C18: EQ | D18: 45678 | E18: 109.88 | F18: =E18/E17-1 -> 9.1016656e-05 | H18: 45678 | I18: 23024.65 | J18: =I18/I17-1 -> -0.013711862 | P18: 45678 | Q18: 918.9 | R18: =Q18/Q17-1 -> -0.015956308 | T18: 45678 | U18: 41.29 | V18: =U18/U17-1 -> -0.020403321 | X18: 45678 | Y18: 926.85 | Z18: =Y18/Y17-1 -> 0.0083224543 | AB18: 45678 | AC18: 129.7 | AD18: =AC18/AC17-1 -> -0.01488683
B19: SAIL | C19: EQ | D19: 45679 | E19: 107.1 | F19: =E19/E18-1 -> -0.025300328 | H19: 45679 | I19: 23155.35 | J19: =I19/I18-1 -> 0.0056765249 | L19: JSWSTEEL | N19: =SLOPE(Z5:Z252,J5:J252) -> 1.2649217 | O19: BETA | P19: 45679 | Q19: 896.8 | R19: =Q19/Q18-1 -> -0.024050495 | T19: 45679 | U19: 40.51 | V19: =U19/U18-1 -> -0.018890773 | X19: 45679 | Y19: 919.4 | Z19: =Y19/Y18-1 -> -0.0080379781 | AB19: 45679 | AC19: 128.92 | AD19: =AC19/AC18-1 -> -0.0060138782
B20: SAIL | C20: EQ | D20: 45680 | E20: 109.14 | F20: =E20/E19-1 -> 0.019047619 | H20: 45680 | I20: 23205.35 | J20: =I20/I19-1 -> 0.0021593282 | N20: =_xlfn.COVARIANCE.S(Z5:Z252,J$5:J$252)/_xlfn.VAR.S(J$5:J$252) -> 1.2649217 | P20: 45680 | Q20: 893 | R20: =Q20/Q19-1 -> -0.0042372881 | T20: 45680 | U20: 40.5 | V20: =U20/U19-1 -> -0.00024685263 | X20: 45680 | Y20: 929.9 | Z20: =Y20/Y19-1 -> 0.011420492 | AB20: 45680 | AC20: 130.37 | AD20: =AC20/AC19-1 -> 0.011247285
B21: SAIL | C21: EQ | D21: 45681 | E21: 108.17 | F21: =E21/E20-1 -> -0.0088876672 | H21: 45681 | I21: 23092.2 | J21: =I21/I20-1 -> -0.0048760307 | P21: 45681 | Q21: 882.8 | R21: =Q21/Q20-1 -> -0.011422172 | T21: 45681 | U21: 39.84 | V21: =U21/U20-1 -> -0.016296296 | X21: 45681 | Y21: 932.45 | Z21: =Y21/Y20-1 -> 0.0027422303 | AB21: 45681 | AC21: 129.74 | AD21: =AC21/AC20-1 -> -0.0048324001
B22: SAIL | C22: EQ | D22: 45684 | E22: 103.43 | F22: =E22/E21-1 -> -0.043819913 | H22: 45684 | I22: 22829.15 | J22: =I22/I21-1 -> -0.011391292 | P22: 45684 | Q22: 842.65 | R22: =Q22/Q21-1 -> -0.04548029 | T22: 45684 | U22: 38.25 | V22: =U22/U21-1 -> -0.039909639 | X22: 45684 | Y22: 919.35 | Z22: =Y22/Y21-1 -> -0.014049011 | AB22: 45684 | AC22: 126.37 | AD22: =AC22/AC21-1 -> -0.025975027
B23: SAIL | C23: EQ | D23: 45685 | E23: 102.84 | F23: =E23/E22-1 -> -0.0057043411 | H23: 45685 | I23: 22957.25 | J23: =I23/I22-1 -> 0.005611247 | P23: 45685 | Q23: 841.1 | R23: =Q23/Q22-1 -> -0.0018394351 | T23: 45685 | U23: 38.15 | V23: =U23/U22-1 -> -0.0026143791 | X23: 45685 | Y23: 916.15 | Z23: =Y23/Y22-1 -> -0.0034807201 | AB23: 45685 | AC23: 128.62 | AD23: =AC23/AC22-1 -> 0.017804859
B24: SAIL | C24: EQ | D24: 45686 | E24: 104.36 | F24: =E24/E23-1 -> 0.014780241 | H24: 45686 | I24: 23163.1 | J24: =I24/I23-1 -> 0.0089666663 | L24: TATASTEEL | N24: =SLOPE(AD5:AD252,J$5:J$252) -> 1.4583885 | O24: BETA | P24: 45686 | Q24: 849 | R24: =Q24/Q23-1 -> 0.0093924623 | T24: 45686 | U24: 41.37 | V24: =U24/U23-1 -> 0.08440367 | X24: 45686 | Y24: 937.6 | Z24: =Y24/Y23-1 -> 0.023413197 | AB24: 45686 | AC24: 130.8 | AD24: =AC24/AC23-1 -> 0.016949153
B25: SAIL | C25: EQ | D25: 45687 | E25: 105.45 | F25: =E25/E24-1 -> 0.010444615 | H25: 45687 | I25: 23249.5 | J25: =I25/I24-1 -> 0.0037300707 | N25: =_xlfn.COVARIANCE.S(AD5:AD252,J$5:J$252)/_xlfn.VAR.S(J$5:J$252) -> 1.4583885 | P25: 45687 | Q25: 840.05 | R25: =Q25/Q24-1 -> -0.010541814 | T25: 45687 | U25: 40.67 | V25: =U25/U24-1 -> -0.016920474 | X25: 45687 | Y25: 950.85 | Z25: =Y25/Y24-1 -> 0.014131826 | AB25: 45687 | AC25: 131.12 | AD25: =AC25/AC24-1 -> 0.0024464832
B26: SAIL | C26: EQ | D26: 45688 | E26: 107.43 | F26: =E26/E25-1 -> 0.018776671 | H26: 45688 | I26: 23508.4 | J26: =I26/I25-1 -> 0.011135723 | P26: 45688 | Q26: 791.55 | R26: =Q26/Q25-1 -> -0.057734659 | T26: 45688 | U26: 42.14 | V26: =U26/U25-1 -> 0.036144578 | X26: 45688 | Y26: 945 | Z26: =Y26/Y25-1 -> -0.00615239 | AB26: 45688 | AC26: 134.62 | AD26: =AC26/AC25-1 -> 0.026693106
B27: SAIL | C27: EQ | D27: 45689 | E27: 106.53 | F27: =E27/E26-1 -> -0.0083775482 | H27: 45689 | I27: 23482.15 | J27: =I27/I26-1 -> -0.0011166221 | P27: 45689 | Q27: 776.35 | R27: =Q27/Q26-1 -> -0.01920283 | T27: 45689 | U27: 40.47 | V27: =U27/U26-1 -> -0.039629805 | X27: 45689 | Y27: 934.25 | Z27: =Y27/Y26-1 -> -0.011375661 | AB27: 45689 | AC27: 132.97 | AD27: =AC27/AC26-1 -> -0.012256723
B28: SAIL | C28: EQ | D28: 45691 | E28: 102.27 | F28: =E28/E27-1 -> -0.039988736 | H28: 45691 | I28: 23361.05 | J28: =I28/I27-1 -> -0.0051571087 | P28: 45691 | Q28: 807.7 | R28: =Q28/Q27-1 -> 0.040381271 | T28: 45691 | U28: 39.75 | V28: =U28/U27-1 -> -0.017790956 | X28: 45691 | Y28: 933.95 | Z28: =Y28/Y27-1 -> -0.00032111319 | AB28: 45691 | AC28: 131.82 | AD28: =AC28/AC27-1 -> -0.0086485673
B29: SAIL | C29: EQ | D29: 45692 | E29: 106.68 | F29: =E29/E28-1 -> 0.04312115 | H29: 45692 | I29: 23739.25 | J29: =I29/I28-1 -> 0.016189341 | P29: 45692 | Q29: 801.6 | R29: =Q29/Q28-1 -> -0.007552309 | T29: 45692 | U29: 40.01 | V29: =U29/U28-1 -> 0.0065408805 | X29: 45692 | Y29: 944.25 | Z29: =Y29/Y28-1 -> 0.011028428 | AB29: 45692 | AC29: 133.42 | AD29: =AC29/AC28-1 -> 0.012137764
B30: SAIL | C30: EQ | D30: 45693 | E30: 108.84 | F30: =E30/E29-1 -> 0.020247469 | H30: 45693 | I30: 23696.3 | J30: =I30/I29-1 -> -0.00180924 | P30: 45693 | Q30: 818.85 | R30: =Q30/Q29-1 -> 0.021519461 | T30: 45693 | U30: 40.52 | V30: =U30/U29-1 -> 0.012746813 | X30: 45693 | Y30: 949.9 | Z30: =Y30/Y29-1 -> 0.0059835849 | AB30: 45693 | AC30: 134.4 | AD30: =AC30/AC29-1 -> 0.0073452256
B31: SAIL | C31: EQ | D31: 45694 | E31: 107.98 | F31: =E31/E30-1 -> -0.0079015068 | H31: 45694 | I31: 23603.35 | J31: =I31/I30-1 -> -0.0039225533 | P31: 45694 | Q31: 809.35 | R31: =Q31/Q30-1 -> -0.011601636 | T31: 45694 | U31: 40.7 | V31: =U31/U30-1 -> 0.0044422507 | X31: 45694 | Y31: 948.4 | Z31: =Y31/Y30-1 -> -0.0015791136 | AB31: 45694 | AC31: 132.54 | AD31: =AC31/AC30-1 -> -0.013839286
B32: SAIL | C32: EQ | D32: 45695 | E32: 110.32 | F32: =E32/E31-1 -> 0.02167068 | H32: 45695 | I32: 23559.95 | J32: =I32/I31-1 -> -0.001838722 | P32: 45695 | Q32: 844.55 | R32: =Q32/Q31-1 -> 0.043491691 | T32: 45695 | U32: 40.23 | V32: =U32/U31-1 -> -0.011547912 | X32: 45695 | Y32: 980.75 | Z32: =Y32/Y31-1 -> 0.03411008 | AB32: 45695 | AC32: 138.31 | AD32: =AC32/AC31-1 -> 0.043534027
B33: SAIL | C33: EQ | D33: 45698 | E33: 105.18 | F33: =E33/E32-1 -> -0.046591733 | H33: 45698 | I33: 23381.6 | J33: =I33/I32-1 -> -0.00757005 | P33: 45698 | Q33: 840.6 | R33: =Q33/Q32-1 -> -0.0046770469 | T33: 45698 | U33: 39.85 | V33: =U33/U32-1 -> -0.0094456873 | X33: 45698 | Y33: 959.15 | Z33: =Y33/Y32-1 -> -0.022023961 | AB33: 45698 | AC33: 134.04 | AD33: =AC33/AC32-1 -> -0.030872677
B34: SAIL | C34: EQ | D34: 45699 | E34: 100.02 | F34: =E34/E33-1 -> -0.049058756 | H34: 45699 | I34: 23071.8 | J34: =I34/I33-1 -> -0.013249735 | P34: 45699 | Q34: 834.5 | R34: =Q34/Q33-1 -> -0.0072567214 | T34: 45699 | U34: 38.88 | V34: =U34/U33-1 -> -0.02434128 | X34: 45699 | Y34: 954.5 | Z34: =Y34/Y33-1 -> -0.0048480425 | AB34: 45699 | AC34: 130.11 | AD34: =AC34/AC33-1 -> -0.029319606
B35: SAIL | C35: EQ | D35: 45700 | E35: 105.75 | F35: =E35/E34-1 -> 0.057288542 | H35: 45700 | I35: 23045.25 | J35: =I35/I34-1 -> -0.0011507555 | P35: 45700 | Q35: 829.35 | R35: =Q35/Q34-1 -> -0.0061713601 | T35: 45700 | U35: 37.98 | V35: =U35/U34-1 -> -0.023148148 | X35: 45700 | Y35: 956.4 | Z35: =Y35/Y34-1 -> 0.001990571 | AB35: 45700 | AC35: 132.28 | AD35: =AC35/AC34-1 -> 0.016678195
B36: SAIL | C36: EQ | D36: 45701 | E36: 109.33 | F36: =E36/E35-1 -> 0.033853428 | H36: 45701 | I36: 23031.4 | J36: =I36/I35-1 -> -0.00060099153 | P36: 45701 | Q36: 840.5 | R36: =Q36/Q35-1 -> 0.013444264 | T36: 45701 | U36: 38.02 | V36: =U36/U35-1 -> 0.0010531859 | X36: 45701 | Y36: 969.8 | Z36: =Y36/Y35-1 -> 0.014010874 | AB36: 45701 | AC36: 136.25 | AD36: =AC36/AC35-1 -> 0.030012096
B37: SAIL | C37: EQ | D37: 45702 | E37: 105.71 | F37: =E37/E36-1 -> -0.033110766 | H37: 45702 | I37: 22929.25 | J37: =I37/I36-1 -> -0.0044352493 | P37: 45702 | Q37: 833.3 | R37: =Q37/Q36-1 -> -0.0085663296 | T37: 45702 | U37: 37.14 | V37: =U37/U36-1 -> -0.023145713 | X37: 45702 | Y37: 964.6 | Z37: =Y37/Y36-1 -> -0.0053619303 | AB37: 45702 | AC37: 134.47 | AD37: =AC37/AC36-1 -> -0.01306422
... B252: SAIL | C252: EQ | D252: 46022 | E252: 146.99 | F252: =E252/E251-1 -> 0.042334421 | H252: 46022 | I252: 26129.6 | J252: =I252/I251-1 -> 0.0073538341 | P252: 46022 | Q252: 1053.8 | R252: =Q252/Q251-1 -> 0.031822187 | T252: 46022 | U252: 44.25 | V252: =U252/U251-1 -> 0.022648486 | X252: 46022 | Y252: 1164.8 | Z252: =Y252/Y251-1 -> 0.047858942 | AB252: 46022 | AC252: 180.08 | AD252: =AC252/AC251-1 -> 0.024345848

Sheet FcFF
B1: STEEL AUTHORITY OF INDIA LIMITED
B3: All Figure are in INR unless Stated Otherwise
D4: FY 2024-25 (₹ Cr) | I4: FY 2024-25 (₹ Cr)
B5: Name oF Company | C5: Country | D5: Total Equity | E5: Total Debt | F5: Total Cash | G5: Tax Rate 1 | I5: Total Equity | J5: Total Debt | K5: Total Cash
B6: STEEL AUTHORITY OF INDIA LIMITED | C6: Iindia | D6: =IFERROR(SUM('Consolidated Balance Sheet'!B35:B36),0) -> 58905.61 | E6: =IFERROR(SUM('Consolidated Balance Sheet'!B40,'Consolidated Balance Sheet'!B50,'Consolidated Balance Sheet'!B41,'Consolidated Balance Sheet'!B51),0) -> 36933.94 | F6: =IFERROR(SUM('Consolidated Balance Sheet'!B23,'Consolidated Balance Sheet'!B24),0) -> 966.88 | G6: 0.3 | I6: =IFERROR(SUM('Consolidated Balance Sheet'!C35:C36),0) -> 57101.22 | J6: =IFERROR(SUM('Consolidated Balance Sheet'!C40,'Consolidated Balance Sheet'!C41,'Consolidated Balance Sheet'!C50,'Consolidated Balance Sheet'!C51),0) -> 36322.65 | K6: =IFERROR(SUM('Consolidated Balance Sheet'!C23,'Consolidated Balance Sheet'!C24),0) -> 672.95
B10: Total Capital | D10: =SUM(D6:E6) -> 95839.55 | I10: Total Capital | K10: =SUM(I6:J6) -> 93423.87
C11: FY 2024-25 (₹ Cr) | D11: FY 2023-24 (₹ Cr)
B12: Working Notes -No.1 | K12: Factor | L12: Growth
B13: Net Operating Profit Before Tax | C13: =IFERROR(SUM('Consolidated Income Statement'!B19+'Consolidated Income Statement'!B14),0) -> 5870.56 | D13: =IFERROR(SUM('Consolidated Income Statement'!C19+'Consolidated Income Statement'!C14),0) -> 6937.9 | K13: Company (SAIL) | L13: 0
B14: NOPAT | C14: =IFERROR(C13*(1-$G$6),0) -> 4109.392 | D14: =IFERROR(D13*(1-$G$6),0) -> 4856.53 | K14: Industry (Steel) | L14: 6–8%
B15: Invested Capital | C15: =IFERROR(D10-F6,0) -> 94872.67 | D15: =IFERROR(K10-K6,0) -> 92750.92 | K15: GDP (India) | L15: 6–7%
B16: Return on Invested Capital(ROIC) | C16: =IFERROR(C14/C15,0) -> 0.043314813 | D16: =IFERROR(D14/D15,0) -> 0.05236099
B17: Working Notes -No.2 | K17: Working note No.3
B18: Capx | C18: =IFERROR(SUM('Consolidated Balance Sheet'!B6,'Consolidated Balance Sheet'!B7,'Consolidated Balance Sheet'!B8),0) -> 79106.18 | D18: =IFERROR(SUM('Consolidated Balance Sheet'!C6,'Consolidated Balance Sheet'!C7,'Consolidated Balance Sheet'!C8),0) -> 77076.83 | E18: PPE+CWIP(+ Right of Use if required) | K18: 4130525289 | L18: TOTAL NO. EQUITY SHARE
B19: Operating Current Assets | C19: =IFERROR(SUM('Consolidated Balance Sheet'!B21,'Consolidated Balance Sheet'!B22,'Consolidated Balance Sheet'!B28),0) -> 39673.34 | D19: =IFERROR(SUM('Consolidated Balance Sheet'!C21,'Consolidated Balance Sheet'!C22,'Consolidated Balance Sheet'!C28),0) -> 45619.14 | E19: Other Current Assets Consider as operating part
B20: Operating Liabilities Assets | C20: =IFERROR(SUM('Consolidated Balance Sheet'!B52,'Consolidated Balance Sheet'!B53,'Consolidated Balance Sheet'!B55,'Consolidated Balance Sheet'!B56),0) -> 16091.39 | D20: =IFERROR(SUM('Consolidated Balance Sheet'!C52,'Consolidated Balance Sheet'!C53,'Consolidated Balance Sheet'!C55,'Consolidated Balance Sheet'!C56),0) -> 21192.47 | E20: (Provisions included) | K20: =K18/10000000 -> 413.05253 | L20: covert in cr
B21: Change Capx | C21: =IFERROR(C18-D18,0) -> 2029.35 | E21: CapEx = Actual spending during the year
B22: Working capital | C22: =IFERROR(C19-C20,0) -> 23581.95 | D22: =IFERROR(D19-D20,0) -> 24426.67 | E22: WC=OCA−OCL | K22: Conservative estimate
B23: Change in Working capital ΔWC | C23: =IFERROR(C22-D22,0) -> -844.72 | E23: ΔWC=WCcurrent​−WCprevious​ | K23: 4% -5% | L23: 0.045
B24: Deprecation | C24: =IFERROR('Consolidated Income Statement'!B15,0) -> 5650.68
B25: Reinvestment | C25: =IFERROR(C21+(C23)-C24,0) -> -4466.05 | E25: Reinvestment= change in CapEx−Depreciation+ΔWC | H25: CapEx = Actual spending during the year | K25: Optimistic scenario:
B26: Reinvestment Rate | C26: =IFERROR(C25/C14,0) -> -1.0867909 | K26: g = 5% – 6% | L26: 0.05
B28: Working Notes -No.1 *Working Notes -No.2 | K28: Aggressive (not recommended):
B29: FCFF Growth Rate | C29: =C16*C26 -> -0.047074147 | D29: 0.0471 | K29: g = 6% – 7% | L29: 0.065
B31: FCFE Calculation
B32: Profit After Tax | C32: =IFERROR('Consolidated Income Statement'!B30,0) -> 2371.8 | D32: =IFERROR('Consolidated Income Statement'!C30,0) -> 3066.67
B33: Deprecation | C33: =C24 -> 5650.68
B34: Change in Working capital ΔWC | C34: =C23 -> -844.72
B35: Change Capx | C35: =C21 -> 2029.35
B36: Change Debt(Net Borrowings) | C36: =IFERROR(SUM('Consolidated Cash Flow'!D36,'Consolidated Cash Flow'!D37,'Consolidated Cash Flow'!D38),0) -> -789.85 | D36: =IFERROR(SUM('Consolidated Cash Flow'!E36,'Consolidated Cash Flow'!E37,'Consolidated Cash Flow'!E38),0) -> 4939.19 | E36: Consolidated Cash Flow financing activity
B37: FCFE | C37: =IFERROR(C32+C33-C35-(C34)+(C36),0) -> 6048
B38: Ke | C38: =IFERROR(WACC!I10,0) -> 0.14245113
B39: Perpetual Growth | C39: 0.045 | E39: Conservative estimate (recommended for valuation):
B40: Forecast FCFE (5 Years @ -4.5%) | C40: FCFF OP | D40: FCFE(Forecast) | E40: PV of FCFE
B41: FY -25 | C41: =C37 -> 6048 | D41: =C41*(1+C64) -> 5670.5545 | E41: =PV($C$38,5,0,-D41) -> 2913.6499
B42: FY -26 | C42: =D41 -> 5670.5545 | D42: =C42*(1+12%) -> 6351.021 | E42: =PV($C$38,5,0,-D42) -> 3263.2879
B43: FY -27 | C43: =D42 -> 6351.021 | D43: =C43*(1+12%) -> 7113.1436 | E43: =PV($C$38,5,0,-D43) -> 3654.8825
B44: FY -28 | C44: =D43 -> 7113.1436 | D44: =C44*(1+12%) -> 7966.7208 | E44: =PV($C$38,5,0,-D44) -> 4093.4684
B45: FY -29 | C45: =D44 -> 7966.7208 | D45: =C45*(1+12%) -> 8922.7273 | E45: =PV($C$38,5,0,-D45) -> 4584.6846
B46: FY -30 | C46: =D45 -> 8922.7273 | D46: =C46*(1+12%) -> 9993.4546 | E46: =PV($C$38,5,0,-D46) -> 5134.8467
...
